from django.test import TestCase
from django.contrib.auth import get_user_model


class UserManagersTests(TestCase):
    def test_create_user(self):
        User = get_user_model()
        user = User.objects.create_user(
            username="testuser",
            email="testuser@example.com",
            password="testpass1234",
        )
        self.assertEqual(user.username, "testuser")
        self.assertEqual(user.email, "testuser@example.com")
        self.assertTrue(user.is_active)
        self.assertFalse(user.is_staff)
        self.assertFalse(user.is_superuser)

    def test_create_super_user(self):
        User = get_user_model()
        admin_user = User.objects.create_superuser(
            username="testsuperuser",
            email="testsuperuser@example.com",
            password="testpass1234",
        )
        self.assertEqual(admin_user.username, "testsuperuser")
        self.assertEqual(admin_user.email, "testsuperuser@example.com")
        self.assertTrue(admin_user.is_active)
        self.assertTrue(admin_user.is_staff)
        self.assertTrue(admin_user.is_superuser)


"""
% python3 manage.py test
Found 2 test(s).
Creating test database for alias 'default'...
System check identified no issues (0 silenced).
..
----------------------------------------------------------------------
Ran 2 tests in 0.700s

OK
Destroying test database for alias 'default'...
"""
